[2024-09-19 11:36:30,467] 97 werkzeug - INFO - [31m[1mWARNING: This is a development server. Do not use it in a production deployment. Use a production WSGI server instead.[0m
 * Running on all addresses (0.0.0.0)
 * Running on http://127.0.0.1:5000
 * Running on http://10.191.159.31:5000
[2024-09-19 11:36:30,467] 97 werkzeug - INFO - [33mPress CTRL+C to quit[0m
[2024-09-19 11:36:35,543] 97 werkzeug - INFO - 127.0.0.1 - - [19/Sep/2024 11:36:35] "GET /predictdata HTTP/1.1" 200 -
[2024-09-19 11:36:54,362] 838 app - ERROR - Exception on /predictdata [POST]
Traceback (most recent call last):
  File "C:\Users\xz328e\Projects\mlproject-main\learn_mlproject\src\pipeline\predict_pipeline.py", line 19, in predict
    data_scaled=preprocessor.transform(features)
  File "C:\Users\xz328e\Projects\mlproject-main\learn_mlproject\venv\lib\site-packages\sklearn\utils\_set_output.py", line 157, in wrapped
    data_to_wrap = f(self, X, *args, **kwargs)
  File "C:\Users\xz328e\Projects\mlproject-main\learn_mlproject\venv\lib\site-packages\sklearn\compose\_column_transformer.py", line 827, in transform
    Xs = self._fit_transform(
  File "C:\Users\xz328e\Projects\mlproject-main\learn_mlproject\venv\lib\site-packages\sklearn\compose\_column_transformer.py", line 681, in _fit_transform
    return Parallel(n_jobs=self.n_jobs)(
  File "C:\Users\xz328e\Projects\mlproject-main\learn_mlproject\venv\lib\site-packages\sklearn\utils\parallel.py", line 65, in __call__
    return super().__call__(iterable_with_config)
  File "C:\Users\xz328e\Projects\mlproject-main\learn_mlproject\venv\lib\site-packages\joblib\parallel.py", line 1918, in __call__
    return output if self.return_generator else list(output)
  File "C:\Users\xz328e\Projects\mlproject-main\learn_mlproject\venv\lib\site-packages\joblib\parallel.py", line 1847, in _get_sequential_output
    res = func(*args, **kwargs)
  File "C:\Users\xz328e\Projects\mlproject-main\learn_mlproject\venv\lib\site-packages\sklearn\utils\parallel.py", line 127, in __call__
    return self.function(*args, **kwargs)
  File "C:\Users\xz328e\Projects\mlproject-main\learn_mlproject\venv\lib\site-packages\sklearn\pipeline.py", line 940, in _transform_one
    res = transformer.transform(X)
  File "C:\Users\xz328e\Projects\mlproject-main\learn_mlproject\venv\lib\site-packages\sklearn\pipeline.py", line 696, in transform
    Xt = transform.transform(Xt)
  File "C:\Users\xz328e\Projects\mlproject-main\learn_mlproject\venv\lib\site-packages\sklearn\utils\_set_output.py", line 157, in wrapped
    data_to_wrap = f(self, X, *args, **kwargs)
  File "C:\Users\xz328e\Projects\mlproject-main\learn_mlproject\venv\lib\site-packages\sklearn\preprocessing\_encoders.py", line 1027, in transform
    X_int, X_mask = self._transform(
  File "C:\Users\xz328e\Projects\mlproject-main\learn_mlproject\venv\lib\site-packages\sklearn\preprocessing\_encoders.py", line 200, in _transform
    raise ValueError(msg)
ValueError: Found unknown categories [None] in column 1 during transform

During handling of the above exception, another exception occurred:

Traceback (most recent call last):
  File "C:\Users\xz328e\Projects\mlproject-main\learn_mlproject\venv\lib\site-packages\flask\app.py", line 1473, in wsgi_app
    response = self.full_dispatch_request()
  File "C:\Users\xz328e\Projects\mlproject-main\learn_mlproject\venv\lib\site-packages\flask\app.py", line 882, in full_dispatch_request
    rv = self.handle_user_exception(e)
  File "C:\Users\xz328e\Projects\mlproject-main\learn_mlproject\venv\lib\site-packages\flask\app.py", line 880, in full_dispatch_request
    rv = self.dispatch_request()
  File "C:\Users\xz328e\Projects\mlproject-main\learn_mlproject\venv\lib\site-packages\flask\app.py", line 865, in dispatch_request
    return self.ensure_sync(self.view_functions[rule.endpoint])(**view_args)  # type: ignore[no-any-return]
  File "app.py", line 33, in predict_datapoint
    results=predict_pipeline.predict(data_df)
  File "C:\Users\xz328e\Projects\mlproject-main\learn_mlproject\src\pipeline\predict_pipeline.py", line 24, in predict
    raise CustomException(e,sys)
src.exception.CustomException: Error occured in python script name [C:\Users\xz328e\Projects\mlproject-main\learn_mlproject\src\pipeline\predict_pipeline.py] line number [19] error message [Found unknown categories [None] in column 1 during transform]
[2024-09-19 11:36:54,367] 97 werkzeug - INFO - 127.0.0.1 - - [19/Sep/2024 11:36:54] "[35m[1mPOST /predictdata HTTP/1.1[0m" 500 -
[2024-09-19 11:38:15,048] 838 app - ERROR - Exception on /predictdata [POST]
Traceback (most recent call last):
  File "C:\Users\xz328e\Projects\mlproject-main\learn_mlproject\src\pipeline\predict_pipeline.py", line 19, in predict
    data_scaled=preprocessor.transform(features)
  File "C:\Users\xz328e\Projects\mlproject-main\learn_mlproject\venv\lib\site-packages\sklearn\utils\_set_output.py", line 157, in wrapped
    data_to_wrap = f(self, X, *args, **kwargs)
  File "C:\Users\xz328e\Projects\mlproject-main\learn_mlproject\venv\lib\site-packages\sklearn\compose\_column_transformer.py", line 827, in transform
    Xs = self._fit_transform(
  File "C:\Users\xz328e\Projects\mlproject-main\learn_mlproject\venv\lib\site-packages\sklearn\compose\_column_transformer.py", line 681, in _fit_transform
    return Parallel(n_jobs=self.n_jobs)(
  File "C:\Users\xz328e\Projects\mlproject-main\learn_mlproject\venv\lib\site-packages\sklearn\utils\parallel.py", line 65, in __call__
    return super().__call__(iterable_with_config)
  File "C:\Users\xz328e\Projects\mlproject-main\learn_mlproject\venv\lib\site-packages\joblib\parallel.py", line 1918, in __call__
    return output if self.return_generator else list(output)
  File "C:\Users\xz328e\Projects\mlproject-main\learn_mlproject\venv\lib\site-packages\joblib\parallel.py", line 1847, in _get_sequential_output
    res = func(*args, **kwargs)
  File "C:\Users\xz328e\Projects\mlproject-main\learn_mlproject\venv\lib\site-packages\sklearn\utils\parallel.py", line 127, in __call__
    return self.function(*args, **kwargs)
  File "C:\Users\xz328e\Projects\mlproject-main\learn_mlproject\venv\lib\site-packages\sklearn\pipeline.py", line 940, in _transform_one
    res = transformer.transform(X)
  File "C:\Users\xz328e\Projects\mlproject-main\learn_mlproject\venv\lib\site-packages\sklearn\pipeline.py", line 696, in transform
    Xt = transform.transform(Xt)
  File "C:\Users\xz328e\Projects\mlproject-main\learn_mlproject\venv\lib\site-packages\sklearn\utils\_set_output.py", line 157, in wrapped
    data_to_wrap = f(self, X, *args, **kwargs)
  File "C:\Users\xz328e\Projects\mlproject-main\learn_mlproject\venv\lib\site-packages\sklearn\preprocessing\_encoders.py", line 1027, in transform
    X_int, X_mask = self._transform(
  File "C:\Users\xz328e\Projects\mlproject-main\learn_mlproject\venv\lib\site-packages\sklearn\preprocessing\_encoders.py", line 200, in _transform
    raise ValueError(msg)
ValueError: Found unknown categories [None] in column 1 during transform

During handling of the above exception, another exception occurred:

Traceback (most recent call last):
  File "C:\Users\xz328e\Projects\mlproject-main\learn_mlproject\venv\lib\site-packages\flask\app.py", line 1473, in wsgi_app
    response = self.full_dispatch_request()
  File "C:\Users\xz328e\Projects\mlproject-main\learn_mlproject\venv\lib\site-packages\flask\app.py", line 882, in full_dispatch_request
    rv = self.handle_user_exception(e)
  File "C:\Users\xz328e\Projects\mlproject-main\learn_mlproject\venv\lib\site-packages\flask\app.py", line 880, in full_dispatch_request
    rv = self.dispatch_request()
  File "C:\Users\xz328e\Projects\mlproject-main\learn_mlproject\venv\lib\site-packages\flask\app.py", line 865, in dispatch_request
    return self.ensure_sync(self.view_functions[rule.endpoint])(**view_args)  # type: ignore[no-any-return]
  File "app.py", line 33, in predict_datapoint
    results=predict_pipeline.predict(data_df)
  File "C:\Users\xz328e\Projects\mlproject-main\learn_mlproject\src\pipeline\predict_pipeline.py", line 24, in predict
    raise CustomException(e,sys)
src.exception.CustomException: Error occured in python script name [C:\Users\xz328e\Projects\mlproject-main\learn_mlproject\src\pipeline\predict_pipeline.py] line number [19] error message [Found unknown categories [None] in column 1 during transform]
[2024-09-19 11:38:15,050] 97 werkzeug - INFO - 127.0.0.1 - - [19/Sep/2024 11:38:15] "[35m[1mPOST /predictdata HTTP/1.1[0m" 500 -
[2024-09-19 11:38:18,225] 838 app - ERROR - Exception on /predictdata [POST]
Traceback (most recent call last):
  File "C:\Users\xz328e\Projects\mlproject-main\learn_mlproject\src\pipeline\predict_pipeline.py", line 19, in predict
    data_scaled=preprocessor.transform(features)
  File "C:\Users\xz328e\Projects\mlproject-main\learn_mlproject\venv\lib\site-packages\sklearn\utils\_set_output.py", line 157, in wrapped
    data_to_wrap = f(self, X, *args, **kwargs)
  File "C:\Users\xz328e\Projects\mlproject-main\learn_mlproject\venv\lib\site-packages\sklearn\compose\_column_transformer.py", line 827, in transform
    Xs = self._fit_transform(
  File "C:\Users\xz328e\Projects\mlproject-main\learn_mlproject\venv\lib\site-packages\sklearn\compose\_column_transformer.py", line 681, in _fit_transform
    return Parallel(n_jobs=self.n_jobs)(
  File "C:\Users\xz328e\Projects\mlproject-main\learn_mlproject\venv\lib\site-packages\sklearn\utils\parallel.py", line 65, in __call__
    return super().__call__(iterable_with_config)
  File "C:\Users\xz328e\Projects\mlproject-main\learn_mlproject\venv\lib\site-packages\joblib\parallel.py", line 1918, in __call__
    return output if self.return_generator else list(output)
  File "C:\Users\xz328e\Projects\mlproject-main\learn_mlproject\venv\lib\site-packages\joblib\parallel.py", line 1847, in _get_sequential_output
    res = func(*args, **kwargs)
  File "C:\Users\xz328e\Projects\mlproject-main\learn_mlproject\venv\lib\site-packages\sklearn\utils\parallel.py", line 127, in __call__
    return self.function(*args, **kwargs)
  File "C:\Users\xz328e\Projects\mlproject-main\learn_mlproject\venv\lib\site-packages\sklearn\pipeline.py", line 940, in _transform_one
    res = transformer.transform(X)
  File "C:\Users\xz328e\Projects\mlproject-main\learn_mlproject\venv\lib\site-packages\sklearn\pipeline.py", line 696, in transform
    Xt = transform.transform(Xt)
  File "C:\Users\xz328e\Projects\mlproject-main\learn_mlproject\venv\lib\site-packages\sklearn\utils\_set_output.py", line 157, in wrapped
    data_to_wrap = f(self, X, *args, **kwargs)
  File "C:\Users\xz328e\Projects\mlproject-main\learn_mlproject\venv\lib\site-packages\sklearn\preprocessing\_encoders.py", line 1027, in transform
    X_int, X_mask = self._transform(
  File "C:\Users\xz328e\Projects\mlproject-main\learn_mlproject\venv\lib\site-packages\sklearn\preprocessing\_encoders.py", line 200, in _transform
    raise ValueError(msg)
ValueError: Found unknown categories [None] in column 1 during transform

During handling of the above exception, another exception occurred:

Traceback (most recent call last):
  File "C:\Users\xz328e\Projects\mlproject-main\learn_mlproject\venv\lib\site-packages\flask\app.py", line 1473, in wsgi_app
    response = self.full_dispatch_request()
  File "C:\Users\xz328e\Projects\mlproject-main\learn_mlproject\venv\lib\site-packages\flask\app.py", line 882, in full_dispatch_request
    rv = self.handle_user_exception(e)
  File "C:\Users\xz328e\Projects\mlproject-main\learn_mlproject\venv\lib\site-packages\flask\app.py", line 880, in full_dispatch_request
    rv = self.dispatch_request()
  File "C:\Users\xz328e\Projects\mlproject-main\learn_mlproject\venv\lib\site-packages\flask\app.py", line 865, in dispatch_request
    return self.ensure_sync(self.view_functions[rule.endpoint])(**view_args)  # type: ignore[no-any-return]
  File "app.py", line 33, in predict_datapoint
    results=predict_pipeline.predict(data_df)
  File "C:\Users\xz328e\Projects\mlproject-main\learn_mlproject\src\pipeline\predict_pipeline.py", line 24, in predict
    raise CustomException(e,sys)
src.exception.CustomException: Error occured in python script name [C:\Users\xz328e\Projects\mlproject-main\learn_mlproject\src\pipeline\predict_pipeline.py] line number [19] error message [Found unknown categories [None] in column 1 during transform]
[2024-09-19 11:38:18,226] 97 werkzeug - INFO - 127.0.0.1 - - [19/Sep/2024 11:38:18] "[35m[1mPOST /predictdata HTTP/1.1[0m" 500 -
